Workbook
Name IQ_CH: 110000
Name IQ_CQ: 5000
Name IQ_CY: 10000
Name IQ_DAILY: 500000
Name IQ_FH: 100000
Name IQ_FQ: 500
Name IQ_FY: 1000
Name IQ_LTM: 2000
Name IQ_MONTH: 15000
Name IQ_NTM: 6000
Name IQ_WEEK: 50000
Name IQ_YTD: 3000

Sheet Data Sheet 
A2: COMPANY NAME | B2: RELIANCE INDUSTRIES LTD | E2: =IF(B3<>B4, "A NEW VERSION OF THE WORKSHEET IS AVAILABLE", "")
A3: LATEST VERSION | B3: 2.1 | E3: PLEASE DO NOT MAKE ANY CHANGES TO THIS SHEET
A4: CURRENT VERSION | B4: 2.1
A6: META
A7: Number of shares | B7: =IF(B10>0, B10/B9, 0) -> 1353.8808
A8: Face Value | B8: 10
A9: Current Price | B9: 1279
A10: Market Capitalization | B10: 1731613.6
A16: PROFIT & LOSS
A17: Report Date | B17: 42825 | C17: 43190 | D17: 43555 | E17: 43921 | F17: 44286 | G17: 44651 | H17: 45016 | I17: 45382 | J17: 45747 | K17: 46112
A18: Sales | B18: 303954 | C18: 390823 | D18: 568337 | E18: 596679 | F18: 466307 | G18: 694673 | H18: 876396 | I18: 899041 | J18: 962820 | K18: 1055780
A19: Raw Material Cost | B19: 217518 | C19: 276076 | D19: 399167 | E19: 410288 | F19: 301765 | G19: 494449 | H19: 618746 | I19: 590226 | J19: 644813 | K19: 698930
A20: Change in Inventory | B20: 5218 | C20: 8610 | D20: 4680 | E20: 5048 | F20: 9064 | G20: 21457 | H20: 30263 | I20: 4883 | J20: 15124 | K20: 10267
A21: Power and Fuel | B21: 11251 | C21: 14569 | D21: 17029 | E21: 15098 | F21: 13214 | G21: 17902 | H21: 25062 | I21: 22137 | J21: 23823 | K21: 22069
A22: Other Mfr. Exp | B22: 9909 | C22: 9691 | D22: 12198 | E22: 11434 | F22: 7687 | G22: 12174 | H22: 19658 | I22: 18276 | J22: 18358 | K22: 21162
A23: Employee Cost | B23: 8388 | C23: 9523 | D23: 12488 | E23: 14075 | F23: 14817 | G23: 18758 | H23: 24872 | I23: 25679 | J23: 28559 | K23: 30318
A24: Selling and admin | B24: 18520 | C24: 29111 | D24: 50221 | E24: 62622 | F24: 56154 | G24: 63513 | H24: 67369 | I24: 77292 | J24: 88760 | K24: 104723
A25: Other Expenses | B25: -2721 | C25: -3852 | D25: -2336 | E25: -1056 | F25: 944 | G25: 753 | H25: 8634 | I25: 7816 | J25: 8033 | K25: 9780
A26: Other Income | B26: 9222 | C26: 9869 | D26: 8406 | E26: 8570 | F26: 22432 | G26: 19600 | H26: 12020 | I26: 15792 | J26: 17824 | K26: 28846
A27: Depreciation | B27: 11646 | C27: 16706 | D27: 20934 | E27: 22203 | F27: 26572 | G27: 29782 | H27: 40303 | I27: 50832 | J27: 53136 | K27: 57688
A28: Interest | B28: 3849 | C28: 8052 | D28: 16495 | E28: 22027 | F28: 21189 | G28: 14584 | H28: 19571 | I28: 23118 | J28: 24269 | K28: 27061
... A32: Dividend Amount | B32: 3254.9 | C32: 3553.2 | D32: 3851.9 | E32: 4120.35 | F32: 4511.5 | G32: 5412 | H32: 6089.4 | I32: 6766 | J32: 7442.6 | K32: 8119.2
A41: Quarters
A42: Report Date | B42: 45382 | C42: 45473 | D42: 45565 | E42: 45657 | F42: 45747 | G42: 45838 | H42: 45930 | I42: 46022 | J42: 46112 | K42: 46203
A43: Sales | B43: 236533 | C43: 231784 | D43: 231535 | E43: 239986 | F43: 261388 | G43: 243632 | H43: 254623 | I43: 264905 | J43: 294059 | K43: 309468
A44: Expenses | B44: 194017 | C44: 193019 | D44: 192477 | E44: 196197 | F44: 217556 | G44: 200727 | H44: 208738 | I44: 218887 | J44: 249918 | K44: 261951
A45: Other Income | B45: 4534 | C45: 3983 | D45: 4876 | E45: 4214 | F45: 4905 | G45: 15119 | H45: 4482 | I45: 4914 | J45: 4447 | K45: 6550
A46: Depreciation | B46: 13569 | C46: 13596 | D46: 12880 | E46: 13181 | F46: 13479 | G46: 13842 | H46: 14416 | I46: 14622 | J46: 14808 | K46: 15100
A47: Interest | B47: 5761 | C47: 5918 | D47: 6017 | E47: 6179 | F47: 6155 | G47: 7036 | H47: 6827 | I47: 6613 | J47: 6585 | K47: 8337
A48: Profit before tax | B48: 27720 | C48: 23234 | D48: 25037 | E48: 28643 | F48: 29103 | G48: 37146 | H48: 29124 | I48: 29697 | J48: 27195 | K48: 30630
A49: Tax | B49: 6577 | C49: 5786 | D49: 5936 | E49: 6839 | F49: 6669 | G49: 6465 | H49: 6978 | I49: 7530 | J49: 6579 | K49: 7629
A50: Net profit | B50: 18951 | C50: 15138 | D50: 16563 | E50: 18540 | F50: 19407 | G50: 26994 | H50: 18165 | I50: 18645 | J50: 16971 | K50: 20946
A51: Operating Profit | B51: 42516 | C51: 38765 | D51: 39058 | E51: 43789 | F51: 43832 | G51: 42905 | H51: 45885 | I51: 46018 | J51: 44141 | K51: 47517
A56: BALANCE SHEET
A57: Report Date | B57: 42825 | C57: 43190 | D57: 43555 | E57: 43921 | F57: 44286 | G57: 44651 | H57: 45016 | I57: 45382 | J57: 45747 | K57: 46112
A58: Equity Share Capital | B58: 2959 | C58: 5922 | D58: 5926 | E58: 6339 | F58: 6445 | G58: 6765 | H58: 6766 | I58: 6766 | J58: 13532 | K58: 13532
A59: Reserves | B59: 260750 | C59: 287584 | D59: 381186 | E59: 442827 | F59: 693727 | G59: 772720 | H59: 709106 | I59: 786715 | J59: 829668 | K59: 890498
A60: Borrowings | B60: 217475 | C60: 239843 | D60: 307714 | E60: 355133 | F60: 278962 | G60: 319158 | H60: 451664 | I60: 350719 | J60: 374313 | K60: 402962
A61: Other Liabilities | B61: 225618 | C61: 277924 | D61: 302804 | E61: 358716 | F61: 340931 | G61: 399979 | H61: 438346 | I61: 610848 | J61: 732200 | K61: 870554
A62: Total | B62: 706802 | C62: 811273 | D62: 997630 | E62: 1163015 | F62: 1320065 | G62: 1498622 | H62: 1605882 | I62: 1755048 | J62: 1949713 | K62: 2177546
...

Sheet HistoricalFS
B8: ="Historical Financial Statement-"&'Data Sheet '!B2 -> Historical Financial Statement-RELIANCE INDUSTRIES LTD
B9: Year | C9: ='Data Sheet '!B17 -> 42825 | D9: ='Data Sheet '!C17 -> 43190 | E9: ='Data Sheet '!D17 -> 43555 | F9: ='Data Sheet '!E17 -> 43921 | G9: ='Data Sheet '!F17 -> 44286 | H9: ='Data Sheet '!G17 -> 44651 | I9: ='Data Sheet '!H17 -> 45016 | J9: ='Data Sheet '!I17 -> 45382 | ... L9: ='Data Sheet '!K17 -> 46112
A11: # | B11: Income Statement
B12: Sales | C12: =IFERROR('Data Sheet '!B18,0) -> 303954 | D12: =IFERROR('Data Sheet '!C18,0) -> 390823 | E12: =IFERROR('Data Sheet '!D18,0) -> 568337 | F12: =IFERROR('Data Sheet '!E18,0) -> 596679 | G12: =IFERROR('Data Sheet '!F18,0) -> 466307 | H12: =IFERROR('Data Sheet '!G18,0) -> 694673 | I12: =IFERROR('Data Sheet '!H18,0) -> 876396 | J12: =IFERROR('Data Sheet '!I18,0) -> 899041 | ... L12: =IFERROR('Data Sheet '!K18,0) -> 1055780
B13: Sales % Growth | D13: =D12/C12-1 -> 0.28579654 | E13: =E12/D12-1 -> 0.45420561 | F13: =F12/E12-1 -> 0.0498683 | G13: =G12/F12-1 -> -0.21849604 | H13: =H12/G12-1 -> 0.48973316 | I13: =I12/H12-1 -> 0.26159502 | J13: =J12/I12-1 -> 0.025838776 | K13: =K12/J12-1 -> 0.070941147 | L13: =L12/K12-1 -> 0.096549719
B15: ='Data Sheet '!A20 -> Change in Inventory | C15: ='Data Sheet '!B20 -> 5218 | D15: ='Data Sheet '!C20 -> 8610 | E15: ='Data Sheet '!D20 -> 4680 | F15: ='Data Sheet '!E20 -> 5048 | G15: ='Data Sheet '!F20 -> 9064 | H15: ='Data Sheet '!G20 -> 21457 | I15: ='Data Sheet '!H20 -> 30263 | ... L15: ='Data Sheet '!K20 -> 10267
B17: ='Data Sheet '!A19 -> Raw Material Cost | C17: =IFERROR('Data Sheet '!B19,0) -> 217518 | D17: =IFERROR('Data Sheet '!C19,0) -> 276076 | E17: =IFERROR('Data Sheet '!D19,0) -> 399167 | F17: =IFERROR('Data Sheet '!E19,0) -> 410288 | G17: =IFERROR('Data Sheet '!F19,0) -> 301765 | H17: =IFERROR('Data Sheet '!G19,0) -> 494449 | I17: =IFERROR('Data Sheet '!H19,0) -> 618746 | J17: =IFERROR('Data Sheet '!I19,0) -> 590226 | ... L17: =IFERROR('Data Sheet '!K19,0) -> 698930
B18: ='Data Sheet '!A21 -> Power and Fuel | C18: =IFERROR('Data Sheet '!B21,0) -> 11251 | D18: =IFERROR('Data Sheet '!C21,0) -> 14569 | E18: =IFERROR('Data Sheet '!D21,0) -> 17029 | F18: =IFERROR('Data Sheet '!E21,0) -> 15098 | G18: =IFERROR('Data Sheet '!F21,0) -> 13214 | H18: =IFERROR('Data Sheet '!G21,0) -> 17902 | I18: =IFERROR('Data Sheet '!H21,0) -> 25062 | J18: =IFERROR('Data Sheet '!I21,0) -> 22137 | ... L18: =IFERROR('Data Sheet '!K21,0) -> 22069
B19: ='Data Sheet '!A22 -> Other Mfr. Exp | C19: =IFERROR('Data Sheet '!B22,0) -> 9909 | D19: =IFERROR('Data Sheet '!C22,0) -> 9691 | E19: =IFERROR('Data Sheet '!D22,0) -> 12198 | F19: =IFERROR('Data Sheet '!E22,0) -> 11434 | G19: =IFERROR('Data Sheet '!F22,0) -> 7687 | H19: =IFERROR('Data Sheet '!G22,0) -> 12174 | I19: =IFERROR('Data Sheet '!H22,0) -> 19658 | J19: =IFERROR('Data Sheet '!I22,0) -> 18276 | ... L19: =IFERROR('Data Sheet '!K22,0) -> 21162
B20: ='Data Sheet '!A23 -> Employee Cost | C20: =IFERROR('Data Sheet '!B23,0) -> 8388 | D20: =IFERROR('Data Sheet '!C23,0) -> 9523 | E20: =IFERROR('Data Sheet '!D23,0) -> 12488 | F20: =IFERROR('Data Sheet '!E23,0) -> 14075 | G20: =IFERROR('Data Sheet '!F23,0) -> 14817 | H20: =IFERROR('Data Sheet '!G23,0) -> 18758 | I20: =IFERROR('Data Sheet '!H23,0) -> 24872 | J20: =IFERROR('Data Sheet '!I23,0) -> 25679 | ... L20: =IFERROR('Data Sheet '!K23,0) -> 30318
B22: COGS | C22: =IFERROR(SUM(C17,C18,C19,C20),0) -> 247066 | D22: =IFERROR(SUM(D17,D18,D19,D20),0) -> 309859 | E22: =IFERROR(SUM(E17,E18,E19,E20),0) -> 440882 | F22: =IFERROR(SUM(F17,F18,F19,F20),0) -> 450895 | G22: =IFERROR(SUM(G17,G18,G19,G20),0) -> 337483 | H22: =IFERROR(SUM(H17,H18,H19,H20),0) -> 543283 | I22: =IFERROR(SUM(I17,I18,I19,I20),0) -> 688338 | J22: =IFERROR(SUM(J17,J18,J19,J20),0) -> 656318 | ... L22: =IFERROR(SUM(L17,L18,L19,L20),0) -> 772479
B23: COGS % Sales | C23: =C22/C12 -> 0.8128401 | D23: =D22/D12 -> 0.79283717 | E23: =E22/E12 -> 0.77574045 | F23: =F22/F12 -> 0.75567432 | G23: =G22/G12 -> 0.72373565 | H23: =H22/H12 -> 0.78207013 | I23: =I22/I12 -> 0.78541892 | J23: =J22/J12 -> 0.7300201 | ... L23: =L22/L12 -> 0.73166664
B25: Gross Profit | C25: =IFERROR(SUM(C12,C15)-C22,0) -> 62106 | D25: =IFERROR(SUM(D12,D15)-D22,0) -> 89574 | E25: =IFERROR(SUM(E12,E15)-E22,0) -> 132135 | F25: =IFERROR(SUM(F12,F15)-F22,0) -> 150832 | G25: =IFERROR(SUM(G12,G15)-G22,0) -> 137888 | H25: =IFERROR(SUM(H12,H15)-H22,0) -> 172847 | I25: =IFERROR(SUM(I12,I15)-I22,0) -> 218321 | J25: =IFERROR(SUM(J12,J15)-J22,0) -> 247606 | ... L25: =IFERROR(SUM(L12,L15)-L22,0) -> 293568
B26: Gross Profit Margins | C26: =C25/C12 -> 0.20432697 | D26: =D25/D12 -> 0.22919327 | E26: =E25/E12 -> 0.2324941 | F26: =F25/F12 -> 0.25278584 | G26: =G25/G12 -> 0.29570219 | H26: =H25/H12 -> 0.24881779 | I26: =I25/I12 -> 0.24911227 | J26: =J25/J12 -> 0.27541124 | ... L26: =L25/L12 -> 0.27805793
B28: ='Data Sheet '!A24 -> Selling and admin | C28: ='Data Sheet '!B24 -> 18520 | D28: ='Data Sheet '!C24 -> 29111 | E28: ='Data Sheet '!D24 -> 50221 | F28: ='Data Sheet '!E24 -> 62622 | G28: ='Data Sheet '!F24 -> 56154 | H28: ='Data Sheet '!G24 -> 63513 | I28: ='Data Sheet '!H24 -> 67369 | ... L28: ='Data Sheet '!K24 -> 104723
B29: S&A Exp % Sales | C29: =C28/C12 -> 0.060930272 | D29: =D28/D12 -> 0.074486404 | E29: =E28/E12 -> 0.088364826 | F29: =F28/F12 -> 0.1049509 | G29: =G28/G12 -> 0.12042281 | H29: =H28/H12 -> 0.091428629 | I29: =I28/I12 -> 0.076870501 | J29: =J28/J12 -> 0.085971608 | ... L29: =L28/L12 -> 0.099190172
B31: ='Data Sheet '!A26 -> Other Income | C31: ='Data Sheet '!B26 -> 9222 | D31: ='Data Sheet '!C26 -> 9869 | E31: ='Data Sheet '!D26 -> 8406 | F31: ='Data Sheet '!E26 -> 8570 | G31: ='Data Sheet '!F26 -> 22432 | H31: ='Data Sheet '!G26 -> 19600 | I31: ='Data Sheet '!H26 -> 12020 | ... L31: ='Data Sheet '!K26 -> 28846
B32: Other income % Sales | C32: =C31/C12 -> 0.030340117 | D32: =D31/D12 -> 0.02525184 | E32: =E31/E12 -> 0.01479052 | F32: =F31/F12 -> 0.014362832 | G32: =G31/G12 -> 0.048105647 | H32: =H31/H12 -> 0.028214714 | I32: =I31/I12 -> 0.013715261 | J32: =J31/J12 -> 0.017565384 | ... L32: =L31/L12 -> 0.02732198
B34: ='Data Sheet '!A25 -> Other Expenses | C34: ='Data Sheet '!B25 -> -2721 | D34: ='Data Sheet '!C25 -> -3852 | E34: ='Data Sheet '!D25 -> -2336 | F34: ='Data Sheet '!E25 -> -1056 | G34: ='Data Sheet '!F25 -> 944 | H34: ='Data Sheet '!G25 -> 753 | I34: ='Data Sheet '!H25 -> 8634 | ... L34: ='Data Sheet '!K25 -> 9780
B35: Expense % Sales | C35: =C34/C12 -> -0.0089520125 | D35: =D34/D12 -> -0.0098561241 | E35: =E34/E12 -> -0.0041102374 | F35: =F34/F12 -> -0.0017697958 | G35: =G34/G12 -> 0.0020244174 | H35: =H34/H12 -> 0.0010839632 | I35: =I34/I12 -> 0.0098517109 | J35: =J34/J12 -> 0.0086937081 | ... L35: =L34/L12 -> 0.0092632935
B37: EBITDA | C37: =IFERROR(SUM(C25,C31)-C28-C34,0) -> 55529 | D37: =IFERROR(SUM(D25,D31)-D28-D34,0) -> 74184 | E37: =IFERROR(SUM(E25,E31)-E28-E34,0) -> 92656 | F37: =IFERROR(SUM(F25,F31)-F28-F34,0) -> 97836 | G37: =IFERROR(SUM(G25,G31)-G28-G34,0) -> 103222 | H37: =IFERROR(SUM(H25,H31)-H28-H34,0) -> 128181 | I37: =IFERROR(SUM(I25,I31)-I28-I34,0) -> 154338 | J37: =IFERROR(SUM(J25,J31)-J28-J34,0) -> 178290 | ... L37: =IFERROR(SUM(L25,L31)-L28-L34,0) -> 207911
B38: EBITDA % Margins | C38: =C37/C12 -> 0.18268883 | D38: =D37/D12 -> 0.18981483 | E38: =E37/E12 -> 0.16303003 | F38: =F37/F12 -> 0.16396756 | G38: =G37/G12 -> 0.22136061 | H38: =H37/H12 -> 0.18451991 | I38: =I37/I12 -> 0.17610532 | J38: =J37/J12 -> 0.19831131 | ... L38: =L37/L12 -> 0.19692644
B40: ='Data Sheet '!A27 -> Depreciation | C40: ='Data Sheet '!B27 -> 11646 | D40: ='Data Sheet '!C27 -> 16706 | E40: ='Data Sheet '!D27 -> 20934 | F40: ='Data Sheet '!E27 -> 22203 | G40: ='Data Sheet '!F27 -> 26572 | H40: ='Data Sheet '!G27 -> 29782 | I40: ='Data Sheet '!H27 -> 40303 | ... L40: ='Data Sheet '!K27 -> 57688
B41: Depreciation % Sales | C41: =C40/C12 -> 0.038315008 | D41: =D40/D12 -> 0.042745693 | E41: =E40/E12 -> 0.03683378 | F41: =F40/F12 -> 0.037210963 | G41: =G40/G12 -> 0.056983918 | H41: =H40/H12 -> 0.04287197 | I41: =I40/I12 -> 0.045987202 | J41: =J40/J12 -> 0.056540247 | ... L41: =L40/L12 -> 0.054640171
B43: ='Data Sheet '!A28 -> Interest | C43: ='Data Sheet '!B28 -> 3849 | D43: ='Data Sheet '!C28 -> 8052 | E43: ='Data Sheet '!D28 -> 16495 | F43: ='Data Sheet '!E28 -> 22027 | G43: ='Data Sheet '!F28 -> 21189 | H43: ='Data Sheet '!G28 -> 14584 | I43: ='Data Sheet '!H28 -> 19571 | ... L43: ='Data Sheet '!K28 -> 27061
B44: Interest % Sales | C44: =C43/C12 -> 0.0126631 | D44: =D43/D12 -> 0.020602677 | E44: =E43/E12 -> 0.029023273 | F44: =F43/F12 -> 0.036915997 | G44: =G43/G12 -> 0.045440021 | H44: =H43/H12 -> 0.02099405 | I44: =I43/I12 -> 0.022331229 | J44: =J43/J12 -> 0.025714066 | ... L44: =L43/L12 -> 0.025631287
B46: Earning Before Tax | C46: =IFERROR(C37-(SUM(C40,C43)),0) -> 40034 | D46: =IFERROR(D37-(SUM(D40,D43)),0) -> 49426 | E46: =IFERROR(E37-(SUM(E40,E43)),0) -> 55227 | F46: =IFERROR(F37-(SUM(F40,F43)),0) -> 53606 | G46: =IFERROR(G37-(SUM(G40,G43)),0) -> 55461 | H46: =IFERROR(H37-(SUM(H40,H43)),0) -> 83815 | I46: =IFERROR(I37-(SUM(I40,I43)),0) -> 94464 | J46: =IFERROR(J37-(SUM(J40,J43)),0) -> 104340 | ... L46: =IFERROR(L37-(SUM(L40,L43)),0) -> 123162
B47: EBT Margins | C47: =C46/C12 -> 0.13171072 | D47: =D46/D12 -> 0.12646646 | E47: =E46/E12 -> 0.09717298 | F47: =F46/F12 -> 0.089840601 | G47: =G46/G12 -> 0.11893667 | H47: =H46/H12 -> 0.12065389 | I47: =I46/I12 -> 0.10778689 | J47: =J46/J12 -> 0.116057 | ... L47: =L46/L12 -> 0.11665498
B49: ='Data Sheet '!A30 -> Tax | C49: =IFERROR('Data Sheet '!B30,0) -> 10201 | D49: =IFERROR('Data Sheet '!C30,0) -> 13346 | E49: =IFERROR('Data Sheet '!D30,0) -> 15390 | F49: =IFERROR('Data Sheet '!E30,0) -> 13726 | G49: =IFERROR('Data Sheet '!F30,0) -> 1722 | H49: =IFERROR('Data Sheet '!G30,0) -> 15970 | I49: =IFERROR('Data Sheet '!H30,0) -> 20376 | J49: =IFERROR('Data Sheet '!I30,0) -> 25707 | ... L49: =IFERROR('Data Sheet '!K30,0) -> 27552
B50: Effective Tax Rate | C50: =C49/C46 -> 0.25480841 | D50: =D49/D46 -> 0.27001983 | E50: =E49/E46 -> 0.27866804 | F50: =F49/F46 -> 0.25605343 | G50: =G49/G46 -> 0.031048845 | H50: =H49/H46 -> 0.19053869 | I50: =I49/I46 -> 0.21570122 | J50: =J49/J46 -> 0.24637723 | ... L50: =L49/L46 -> 0.22370536
B52: Net Profit | C52: =IFERROR(C46-C49,0) -> 29833 | D52: =IFERROR(D46-D49,0) -> 36080 | E52: =IFERROR(E46-E49,0) -> 39837 | F52: =IFERROR(F46-F49,0) -> 39880 | G52: =IFERROR(G46-G49,0) -> 53739 | H52: =IFERROR(H46-H49,0) -> 67845 | I52: =IFERROR(I46-I49,0) -> 74088 | J52: =IFERROR(J46-J49,0) -> 78633 | ... L52: =IFERROR(L46-L49,0) -> 95610
B53: Net Margin | C53: =C52/C12 -> 0.09814972 | D53: =D52/D12 -> 0.092318006 | E53: =E52/E12 -> 0.070093976 | F53: =F52/F12 -> 0.066836607 | G53: =G52/G12 -> 0.11524382 | H53: =H52/H12 -> 0.097664657 | I53: =I52/I12 -> 0.084537127 | J53: =J52/J12 -> 0.087463197 | ... L53: =L52/L12 -> 0.090558639
B55: No of equity Shares | C55: =IFERROR('Data Sheet '!B94,0) -> 1387.22 | D55: =IFERROR('Data Sheet '!C94,0) -> 1351.39 | E55: =IFERROR('Data Sheet '!D94,0) -> 1352.26 | F55: =IFERROR('Data Sheet '!E94,0) -> 1352.37 | G55: =IFERROR('Data Sheet '!F94,0) -> 1267.89 | H55: =IFERROR('Data Sheet '!G94,0) -> 1352.98 | I55: =IFERROR('Data Sheet '!H94,0) -> 1353.12 | J55: =IFERROR('Data Sheet '!I94,0) -> 1353.14 | ... L55: =IFERROR('Data Sheet '!K94,0) -> 1353.25
B57: Earnings per Share | C57: =C52/C55 -> 21.505601 | D57: =D52/D55 -> 26.698436 | E57: =E52/E55 -> 29.459571 | F57: =F52/F55 -> 29.488971 | G57: =G52/G55 -> 42.384592 | H57: =H52/H55 -> 50.144865 | I57: =I52/I55 -> 54.753459 | J57: =J52/J55 -> 58.111504 | ... L57: =L52/L55 -> 70.652134
B58: EPS Growth | D58: =D57/C57-1 -> 0.24146432 | E58: =E57/D57-1 -> 0.10341935 | F58: =F57/E57-1 -> 0.00099797207 | G58: =G57/F57-1 -> 0.43730317 | H58: =H57/G57-1 -> 0.18309186 | I58: =I57/H57-1 -> 0.091905586 | J58: =J57/I57-1 -> 0.06133028 | K58: =K57/J57-1 -> 0.027317158 | L58: =L57/K57-1 -> 0.18347375
B60: Dividend Per Share | C60: =IFERROR(C63/C55,0) -> 2.3463474 | D60: =IFERROR(D63/D55,0) -> 2.6292928 | E60: =IFERROR(E63/E55,0) -> 2.8484907 | F60: =IFERROR(F63/F55,0) -> 3.0467624 | G60: =IFERROR(G63/G55,0) -> 3.558274 | H60: =IFERROR(H63/H55,0) -> 4.0000591 | I60: =IFERROR(I63/I55,0) -> 4.5002661 | J60: =IFERROR(J63/J55,0) -> 5.0002217 | ... L60: =IFERROR(L63/L55,0) -> 5.9997783
B61: Dividend Payout Ratio | C61: =C60/C57 -> 0.10910401 | D61: =D60/D57 -> 0.098481153 | E61: =E60/E57 -> 0.096691518 | F61: =F60/F57 -> 0.10331871 | G61: =G60/G57 -> 0.083952065 | H61: =H60/H57 -> 0.079770064 | I61: =I60/I57 -> 0.082191448 | J61: =J60/J57 -> 0.086045299 | ... L61: =L60/L57 -> 0.084919987
B63: Divident Amount | C63: =IFERROR('Data Sheet '!B32,0) -> 3254.9 | D63: =IFERROR('Data Sheet '!C32,0) -> 3553.2 | E63: =IFERROR('Data Sheet '!D32,0) -> 3851.9 | F63: =IFERROR('Data Sheet '!E32,0) -> 4120.35 | G63: =IFERROR('Data Sheet '!F32,0) -> 4511.5 | H63: =IFERROR('Data Sheet '!G32,0) -> 5412 | I63: =IFERROR('Data Sheet '!H32,0) -> 6089.4 | J63: =IFERROR('Data Sheet '!I32,0) -> 6766 | ... L63: =IFERROR('Data Sheet '!K32,0) -> 8119.2
B65: Retained Earnings | C65: =IFERROR(IF(C57>C60,1-C61,0),0) -> 0.89089599 | D65: =IFERROR(IF(D57>D60,1-D61,0),0) -> 0.90151885 | E65: =IFERROR(IF(E57>E60,1-E61,0),0) -> 0.90330848 | F65: =IFERROR(IF(F57>F60,1-F61,0),0) -> 0.89668129 | G65: =IFERROR(IF(G57>G60,1-G61,0),0) -> 0.91604794 | H65: =IFERROR(IF(H57>H60,1-H61,0),0) -> 0.92022994 | I65: =IFERROR(IF(I57>I60,1-I61,0),0) -> 0.91780855 | J65: =IFERROR(IF(J57>J60,1-J61,0),0) -> 0.9139547 | ... L65: =IFERROR(IF(L57>L60,1-L61,0),0) -> 0.91508001
A67: # | B67: Balance Sheet
...

Sheet Ratio Analysis
B8: ="RATIO ANALYSIS-"&'Data Sheet '!B2 -> RATIO ANALYSIS-RELIANCE INDUSTRIES LTD
B9: Year | C9: ='Data Sheet '!B17 -> 42825 | D9: ='Data Sheet '!C17 -> 43190 | E9: ='Data Sheet '!D17 -> 43555 | F9: ='Data Sheet '!E17 -> 43921 | G9: ='Data Sheet '!F17 -> 44286 | H9: ='Data Sheet '!G17 -> 44651 | I9: ='Data Sheet '!H17 -> 45016 | J9: ='Data Sheet '!I17 -> 45382 | ... L9: ='Data Sheet '!K17 -> 46112 | M9: Trend Line | N9: Mean | O9: Median
B11: Sales Growth | D11: =IFERROR(HistoricalFS!D13,0) -> 0.28579654 | E11: =IFERROR(HistoricalFS!E13,0) -> 0.45420561 | F11: =IFERROR(HistoricalFS!F13,0) -> 0.0498683 | G11: =IFERROR(HistoricalFS!G13,0) -> -0.21849604 | H11: =IFERROR(HistoricalFS!H13,0) -> 0.48973316 | I11: =IFERROR(HistoricalFS!I13,0) -> 0.26159502 | J11: =IFERROR(HistoricalFS!J13,0) -> 0.025838776 | K11: =IFERROR(HistoricalFS!K13,0) -> 0.070941147 | L11: =IFERROR(HistoricalFS!L13,0) -> 0.096549719 | N11: =AVERAGE(D11:L11) -> 0.16844803 | O11: =MEDIAN(D11:L11) -> 0.096549719
B12: EBITDA Growth | D12: =IFERROR(HistoricalFS!D37/HistoricalFS!C37-1,0) -> 0.33595058 | E12: =IFERROR(HistoricalFS!E37/HistoricalFS!D37-1,0) -> 0.24900248 | F12: =IFERROR(HistoricalFS!F37/HistoricalFS!E37-1,0) -> 0.055905716 | G12: =IFERROR(HistoricalFS!G37/HistoricalFS!F37-1,0) -> 0.05505131 | H12: =IFERROR(HistoricalFS!H37/HistoricalFS!G37-1,0) -> 0.24179923 | I12: =IFERROR(HistoricalFS!I37/HistoricalFS!H37-1,0) -> 0.204063 | J12: =IFERROR(HistoricalFS!J37/HistoricalFS!I37-1,0) -> 0.15519185 | K12: =IFERROR(HistoricalFS!K37/HistoricalFS!J37-1,0) -> 0.028784564 | L12: =IFERROR(HistoricalFS!L37/HistoricalFS!K37-1,0) -> 0.13351179 | N12: =AVERAGE(D12:L12) -> 0.16214006 | O12: =MEDIAN(D12:L12) -> 0.15519185
B13: EBIT Growth | D13: =IFERROR(HistoricalFS!D46/HistoricalFS!C46-1,0) -> 0.23460059 | E13: =IFERROR(HistoricalFS!E46/HistoricalFS!D46-1,0) -> 0.11736738 | F13: =IFERROR(HistoricalFS!F46/HistoricalFS!E46-1,0) -> -0.029351585 | G13: =IFERROR(HistoricalFS!G46/HistoricalFS!F46-1,0) -> 0.034604335 | H13: =IFERROR(HistoricalFS!H46/HistoricalFS!G46-1,0) -> 0.51124213 | I13: =IFERROR(HistoricalFS!I46/HistoricalFS!H46-1,0) -> 0.12705363 | J13: =IFERROR(HistoricalFS!J46/HistoricalFS!I46-1,0) -> 0.10454776 | K13: =IFERROR(HistoricalFS!K46/HistoricalFS!J46-1,0) -> 0.016072455 | L13: =IFERROR(HistoricalFS!L46/HistoricalFS!K46-1,0) -> 0.16171935 | N13: =AVERAGE(D13:L13) -> 0.14198401 | O13: =MEDIAN(D13:L13) -> 0.11736738
B14: Net Profit Growth | D14: =IFERROR(HistoricalFS!D52/HistoricalFS!C52-1,0) -> 0.20939899 | E14: =IFERROR(HistoricalFS!E52/HistoricalFS!D52-1,0) -> 0.10412971 | F14: =IFERROR(HistoricalFS!F52/HistoricalFS!E52-1,0) -> 0.0010793985 | G14: =IFERROR(HistoricalFS!G52/HistoricalFS!F52-1,0) -> 0.34751755 | H14: =IFERROR(HistoricalFS!H52/HistoricalFS!G52-1,0) -> 0.26249093 | I14: =IFERROR(HistoricalFS!I52/HistoricalFS!H52-1,0) -> 0.092018572 | J14: =IFERROR(HistoricalFS!J52/HistoricalFS!I52-1,0) -> 0.061345967 | K14: =IFERROR(HistoricalFS!K52/HistoricalFS!J52-1,0) -> 0.027393079 | L14: =IFERROR(HistoricalFS!L52/HistoricalFS!K52-1,0) -> 0.18348249 | N14: =AVERAGE(D14:L14) -> 0.1432063 | O14: =MEDIAN(D14:L14) -> 0.10412971
B15: Dividend Growth | D15: =IFERROR(HistoricalFS!D63/HistoricalFS!C63-1,0) -> 0.091646441 | E15: =IFERROR(HistoricalFS!E63/HistoricalFS!D63-1,0) -> 0.084065068 | F15: =IFERROR(HistoricalFS!F63/HistoricalFS!E63-1,0) -> 0.069692879 | G15: =IFERROR(HistoricalFS!G63/HistoricalFS!F63-1,0) -> 0.094931256 | H15: =IFERROR(HistoricalFS!H63/HistoricalFS!G63-1,0) -> 0.19960102 | I15: =IFERROR(HistoricalFS!I63/HistoricalFS!H63-1,0) -> 0.1251663 | J15: =IFERROR(HistoricalFS!J63/HistoricalFS!I63-1,0) -> 0.11111111 | K15: =IFERROR(HistoricalFS!K63/HistoricalFS!J63-1,0) -> 0.1 | L15: =IFERROR(HistoricalFS!L63/HistoricalFS!K63-1,0) -> 0.090909091 | N15: =AVERAGE(D15:L15) -> 0.10745813 | O15: =MEDIAN(D15:L15) -> 0.094931256
B17: Gross Margin | C17: =HistoricalFS!C26 -> 0.20432697 | D17: =HistoricalFS!D26 -> 0.22919327 | E17: =HistoricalFS!E26 -> 0.2324941 | F17: =HistoricalFS!F26 -> 0.25278584 | G17: =HistoricalFS!G26 -> 0.29570219 | H17: =HistoricalFS!H26 -> 0.24881779 | I17: =HistoricalFS!I26 -> 0.24911227 | J17: =HistoricalFS!J26 -> 0.27541124 | ... L17: =HistoricalFS!L26 -> 0.27805793 | N17: =AVERAGE(C17:L17) -> 0.2538425 | O17: =MEDIAN(C17:L17) -> 0.25094905
B18: EBITDA Margin | C18: =HistoricalFS!C38 -> 0.18268883 | D18: =HistoricalFS!D38 -> 0.18981483 | E18: =HistoricalFS!E38 -> 0.16303003 | F18: =HistoricalFS!F38 -> 0.16396756 | G18: =HistoricalFS!G38 -> 0.22136061 | H18: =HistoricalFS!H38 -> 0.18451991 | I18: =HistoricalFS!I38 -> 0.17610532 | J18: =HistoricalFS!J38 -> 0.19831131 | ... L18: =HistoricalFS!L38 -> 0.19692644 | N18: =AVERAGE(C18:L18) -> 0.18672298 | O18: =MEDIAN(C18:L18) -> 0.18716737
B19: EBT Margin | C19: =HistoricalFS!C47 -> 0.13171072 | D19: =HistoricalFS!D47 -> 0.12646646 | E19: =HistoricalFS!E47 -> 0.09717298 | F19: =HistoricalFS!F47 -> 0.089840601 | G19: =HistoricalFS!G47 -> 0.11893667 | H19: =HistoricalFS!H47 -> 0.12065389 | I19: =HistoricalFS!I47 -> 0.10778689 | J19: =HistoricalFS!J47 -> 0.116057 | ... L19: =HistoricalFS!L47 -> 0.11665498 | N19: =AVERAGE(C19:L19) -> 0.11353911 | O19: =MEDIAN(C19:L19) -> 0.11635599
B20: Net Profit Margin | C20: =HistoricalFS!C53 -> 0.09814972 | D20: =HistoricalFS!D53 -> 0.092318006 | E20: =HistoricalFS!E53 -> 0.070093976 | F20: =HistoricalFS!F53 -> 0.066836607 | G20: =HistoricalFS!G53 -> 0.11524382 | H20: =HistoricalFS!H53 -> 0.097664657 | I20: =HistoricalFS!I53 -> 0.084537127 | J20: =HistoricalFS!J53 -> 0.087463197 | ... L20: =HistoricalFS!L53 -> 0.090558639 | N20: =AVERAGE(C20:L20) -> 0.08867724 | O20: =MEDIAN(C20:L20) -> 0.089010918
B22: Selling Expenses % Sales | C22: =HistoricalFS!C29 -> 0.060930272 | D22: =HistoricalFS!D29 -> 0.074486404 | E22: =HistoricalFS!E29 -> 0.088364826 | F22: =HistoricalFS!F29 -> 0.1049509 | G22: =HistoricalFS!G29 -> 0.12042281 | H22: =HistoricalFS!H29 -> 0.091428629 | I22: =HistoricalFS!I29 -> 0.076870501 | J22: =HistoricalFS!J29 -> 0.085971608 | ... L22: =HistoricalFS!L29 -> 0.099190172 | N22: =AVERAGE(C22:L22) -> 0.089480366 | O22: =MEDIAN(C22:L22) -> 0.089896727
B23: Depreciation % Sales | C23: =HistoricalFS!C41 -> 0.038315008 | D23: =HistoricalFS!D41 -> 0.042745693 | E23: =HistoricalFS!E41 -> 0.03683378 | F23: =HistoricalFS!F41 -> 0.037210963 | G23: =HistoricalFS!G41 -> 0.056983918 | H23: =HistoricalFS!H41 -> 0.04287197 | I23: =HistoricalFS!I41 -> 0.045987202 | J23: =HistoricalFS!J41 -> 0.056540247 | ... L23: =HistoricalFS!L41 -> 0.054640171 | N23: =AVERAGE(C23:L23) -> 0.046731684 | O23: =MEDIAN(C23:L23) -> 0.044429586
B24: Operating Income % Sales | C24: =(HistoricalFS!C37-HistoricalFS!C40)/HistoricalFS!C12 -> 0.14437382 | D24: =(HistoricalFS!D37-HistoricalFS!D40)/HistoricalFS!D12 -> 0.14706913 | E24: =(HistoricalFS!E37-HistoricalFS!E40)/HistoricalFS!E12 -> 0.12619625 | F24: =(HistoricalFS!F37-HistoricalFS!F40)/HistoricalFS!F12 -> 0.1267566 | G24: =(HistoricalFS!G37-HistoricalFS!G40)/HistoricalFS!G12 -> 0.16437669 | H24: =(HistoricalFS!H37-HistoricalFS!H40)/HistoricalFS!H12 -> 0.14164794 | I24: =(HistoricalFS!I37-HistoricalFS!I40)/HistoricalFS!I12 -> 0.13011812 | J24: =(HistoricalFS!J37-HistoricalFS!J40)/HistoricalFS!J12 -> 0.14177106 | ... L24: =(HistoricalFS!L37-HistoricalFS!L40)/HistoricalFS!L12 -> 0.14228627 | N24: =AVERAGE(C24:L24) -> 0.1399913 | O24: =MEDIAN(C24:L24) -> 0.1417095
B26: Return on Capital Employed | C26: =(HistoricalFS!C37-HistoricalFS!C40)/SUM(HistoricalFS!C68:C70) -> 0.091197962 | D26: =(HistoricalFS!D37-HistoricalFS!D40)/SUM(HistoricalFS!D68:D70) -> 0.10776808 | E26: =(HistoricalFS!E37-HistoricalFS!E40)/SUM(HistoricalFS!E68:E70) -> 0.10322297 | F26: =(HistoricalFS!F37-HistoricalFS!F40)/SUM(HistoricalFS!F68:F70) -> 0.094035924 | G26: =(HistoricalFS!G37-HistoricalFS!G40)/SUM(HistoricalFS!G68:G70) -> 0.078283463 | H26: =(HistoricalFS!H37-HistoricalFS!H40)/SUM(HistoricalFS!H68:H70) -> 0.089564126 | I26: =(HistoricalFS!I37-HistoricalFS!I40)/SUM(HistoricalFS!I68:I70) -> 0.097671506 | J26: =(HistoricalFS!J37-HistoricalFS!J40)/SUM(HistoricalFS!J68:J70) -> 0.11139486 | ... L26: =(HistoricalFS!L37-HistoricalFS!L40)/SUM(HistoricalFS!L68:L70) -> 0.11493796 | N26: =AVERAGE(C26:L26) -> 0.09950868 | O26: =MEDIAN(C26:L26) -> 0.10044724
B27: Retained Earnings | C27: =HistoricalFS!C65 -> 0.89089599 | D27: =HistoricalFS!D65 -> 0.90151885 | E27: =HistoricalFS!E65 -> 0.90330848 | F27: =HistoricalFS!F65 -> 0.89668129 | G27: =HistoricalFS!G65 -> 0.91604794 | H27: =HistoricalFS!H65 -> 0.92022994 | I27: =HistoricalFS!I65 -> 0.91780855 | J27: =HistoricalFS!J65 -> 0.9139547 | ... L27: =HistoricalFS!L65 -> 0.91508001 | N27: =AVERAGE(C27:L27) -> 0.90833995 | O27: =MEDIAN(C27:L27) -> 0.91091425
B28: Return on Equity | C28: =HistoricalFS!C52/SUM(HistoricalFS!C68:C69) -> 0.11312849 | D28: =HistoricalFS!D52/SUM(HistoricalFS!D68:D69) -> 0.12292764 | E28: =HistoricalFS!E52/SUM(HistoricalFS!E68:E69) -> 0.1029082 | F28: =HistoricalFS!F52/SUM(HistoricalFS!F68:F69) -> 0.088786774 | G28: =HistoricalFS!G52/SUM(HistoricalFS!G68:G69) -> 0.076751141 | H28: =HistoricalFS!H52/SUM(HistoricalFS!H68:H69) -> 0.087038237 | I28: =HistoricalFS!I52/SUM(HistoricalFS!I68:I69) -> 0.10349336 | J28: =HistoricalFS!J52/SUM(HistoricalFS!J68:J69) -> 0.099098781 | ... L28: =HistoricalFS!L52/SUM(HistoricalFS!L68:L69) -> 0.10575976 | N28: =AVERAGE(C28:L28) -> 0.09957024 | O28: =MEDIAN(C28:L28) -> 0.10100349
B29: Self Sustained Growth Rate | C29: =C27*C28 -> 0.10078571 | D29: =D27*D28 -> 0.11082158 | E29: =E27*E28 -> 0.092957852 | F29: =F27*F28 -> 0.079613439 | G29: =G27*G28 -> 0.070307724 | H29: =H27*H28 -> 0.080095191 | I29: =I27*I28 -> 0.094987093 | J29: =J27*J28 -> 0.090571797 | ... L29: =L27*L28 -> 0.096778647 | N29: =AVERAGE(C29:L29) -> 0.090390244 | O29: =MEDIAN(C29:L29) -> 0.091764824
B30: Interest Coverage Ratio | C30: =(HistoricalFS!C37-HistoricalFS!C40)/HistoricalFS!C43 -> 11.401143 | D30: =(HistoricalFS!D37-HistoricalFS!D40)/HistoricalFS!D43 -> 7.1383507 | E30: =(HistoricalFS!E37-HistoricalFS!E40)/HistoricalFS!E43 -> 4.3481055 | F30: =(HistoricalFS!F37-HistoricalFS!F40)/HistoricalFS!F43 -> 3.4336496 | G30: =(HistoricalFS!G37-HistoricalFS!G40)/HistoricalFS!G43 -> 3.617443 | H30: =(HistoricalFS!H37-HistoricalFS!H40)/HistoricalFS!H43 -> 6.7470516 | I30: =(HistoricalFS!I37-HistoricalFS!I40)/HistoricalFS!I43 -> 5.8267334 | J30: =(HistoricalFS!J37-HistoricalFS!J40)/HistoricalFS!J43 -> 5.5133662 | ... L30: =(HistoricalFS!L37-HistoricalFS!L40)/HistoricalFS!L43 -> 5.551273 | N30: =AVERAGE(C30:L30) -> 5.8945529 | O30: =MEDIAN(C30:L30) -> 5.5323196
B32: Debtor Turnover Ratio | C32: =HistoricalFS!C12/HistoricalFS!C80 -> 37.171823 | D32: =HistoricalFS!D12/HistoricalFS!D80 -> 22.262774 | E32: =HistoricalFS!E12/HistoricalFS!E80 -> 18.888531 | F32: =HistoricalFS!F12/HistoricalFS!F80 -> 30.356074 | G32: =HistoricalFS!G12/HistoricalFS!G80 -> 24.524403 | H32: =HistoricalFS!H12/HistoricalFS!H80 -> 29.385491 | I32: =HistoricalFS!I12/HistoricalFS!I80 -> 30.806946 | J32: =HistoricalFS!J12/HistoricalFS!J80 -> 28.425477 | ... L32: =HistoricalFS!L12/HistoricalFS!L80 -> 18.050298 | N32: =AVERAGE(C32:L32) -> 26.273025 | O32: =MEDIAN(C32:L32) -> 26.47494
B33: Creditor Turnover Ratio | C33: =HistoricalFS!C22/HistoricalFS!C71 -> 1.0950633 | D33: =HistoricalFS!D22/HistoricalFS!D71 -> 1.1149055 | E33: =HistoricalFS!E22/HistoricalFS!E71 -> 1.4559979 | F33: =HistoricalFS!F22/HistoricalFS!F71 -> 1.2569693 | G33: =HistoricalFS!G22/HistoricalFS!G71 -> 0.98988652 | H33: =HistoricalFS!H22/HistoricalFS!H71 -> 1.3582788 | I33: =HistoricalFS!I22/HistoricalFS!I71 -> 1.5703075 | J33: =HistoricalFS!J22/HistoricalFS!J71 -> 1.0744375 | ... L33: =HistoricalFS!L22/HistoricalFS!L71 -> 0.88734185 | N33: =AVERAGE(C33:L33) -> 1.1780453 | O33: =MEDIAN(C33:L33) -> 1.1049844
B34: Inventory Turnover | C34: =HistoricalFS!C22/HistoricalFS!C81 -> 5.0472105 | D34: =HistoricalFS!D22/HistoricalFS!D81 -> 5.0932656 | E34: =HistoricalFS!E22/HistoricalFS!E81 -> 6.5256879 | F34: =HistoricalFS!F22/HistoricalFS!F81 -> 6.1011732 | G34: =HistoricalFS!G22/HistoricalFS!G81 -> 4.132175 | H34: =HistoricalFS!H22/HistoricalFS!H81 -> 5.0407597 | I34: =HistoricalFS!I22/HistoricalFS!I81 -> 4.9164191 | J34: =HistoricalFS!J22/HistoricalFS!J81 -> 4.2961183 | ... L34: =HistoricalFS!L22/HistoricalFS!L81 -> 4.6272575 | N34: =AVERAGE(C34:L34) -> 5.0679034 | O34: =MEDIAN(C34:L34) -> 4.9785894
B35: Fixed Asset Turnover | C35: =HistoricalFS!C12/HistoricalFS!C74 -> 1.5310539 | D35: =HistoricalFS!D12/HistoricalFS!D74 -> 0.96765911 | E35: =HistoricalFS!E12/HistoricalFS!E74 -> 1.4266418 | F35: =HistoricalFS!F12/HistoricalFS!F74 -> 1.1201916 | G35: =HistoricalFS!G12/HistoricalFS!G74 -> 0.86152445 | H35: =HistoricalFS!H12/HistoricalFS!H74 -> 1.1065231 | I35: =HistoricalFS!I12/HistoricalFS!I74 -> 1.2091473 | J35: =HistoricalFS!J12/HistoricalFS!J74 -> 1.1526388 | ... L35: =HistoricalFS!L12/HistoricalFS!L74 -> 0.93864215 | N35: =AVERAGE(C35:L35) -> 1.1277427 | O35: =MEDIAN(C35:L35) -> 1.1133573
B36: Capital Turnover Ratio | C36: =HistoricalFS!C12/SUM(HistoricalFS!C68:C69) -> 1.1526114 | D36: =HistoricalFS!D12/SUM(HistoricalFS!D68:D69) -> 1.3315673 | E36: =HistoricalFS!E12/SUM(HistoricalFS!E68:E69) -> 1.4681462 | F36: =HistoricalFS!F12/SUM(HistoricalFS!F68:F69) -> 1.3284153 | G36: =HistoricalFS!G12/SUM(HistoricalFS!G68:G69) -> 0.66598921 | H36: =HistoricalFS!H12/SUM(HistoricalFS!H68:H69) -> 0.89119483 | I36: =HistoricalFS!I12/SUM(HistoricalFS!I68:I69) -> 1.2242356 | J36: =HistoricalFS!J12/SUM(HistoricalFS!J68:J69) -> 1.1330341 | ... L36: =HistoricalFS!L12/SUM(HistoricalFS!L68:L69) -> 1.1678595 | N36: =AVERAGE(C36:L36) -> 1.1504918 | O36: =MEDIAN(C36:L36) -> 1.1602354
B38: Debtor Days | C38: =365/C32 -> 9.8192654 | D38: =365/D32 -> 16.395082 | E38: =365/E32 -> 19.323896 | F38: =365/F32 -> 12.023953 | G38: =365/G32 -> 14.883135 | H38: =365/H32 -> 12.421096 | I38: =365/I32 -> 11.847977 | J38: =365/J32 -> 12.840593 | ... L38: =365/L32 -> 20.221272 | N38: =AVERAGE(C38:L38) -> 14.574412 | O38: =MEDIAN(C38:L38) -> 13.861864
B39: Payable Days | C39: =365/C33 -> 333.31405 | D39: =365/D33 -> 327.382 | E39: =365/E33 -> 250.68717 | F39: =365/F33 -> 290.381 | G39: =365/G33 -> 368.72914 | H39: =365/H33 -> 268.72244 | I39: =365/I33 -> 232.43855 | J39: =365/J33 -> 339.71264 | ... L39: =365/L33 -> 411.3409 | N39: =AVERAGE(C39:L39) -> 319.61995 | O39: =MEDIAN(C39:L39) -> 330.34803
B40: Inventory Days | C40: =365/C34 -> 72.317174 | D40: =365/D34 -> 71.663257 | E40: =365/E34 -> 55.932801 | F40: =365/F34 -> 59.82456 | G40: =365/G34 -> 88.331205 | H40: =365/H34 -> 72.40972 | I40: =365/I34 -> 74.241027 | J40: =365/J34 -> 84.960416 | ... L40: =365/L34 -> 78.880416 | N40: =AVERAGE(C40:L40) -> 73.306607 | O40: =MEDIAN(C40:L40) -> 73.325374
B41: Cash Conversion Cycle (in days) | C41: =SUM(C38,C40)-C39 -> -251.17761 | D41: =SUM(D38,D40)-D39 -> -239.32366 | E41: =SUM(E38,E40)-E39 -> -175.43047 | F41: =SUM(F38,F40)-F39 -> -218.53249 | G41: =SUM(G38,G40)-G39 -> -265.5148 | H41: =SUM(H38,H40)-H39 -> -183.89163 | I41: =SUM(I38,I40)-I39 -> -146.34955 | J41: =SUM(J38,J40)-J39 -> -241.91163 | ... L41: =SUM(L38,L40)-L39 -> -312.23922 | N41: =AVERAGE(C41:L41) -> -231.73893 | O41: =MEDIAN(C41:L41) -> -240.61765
B43: CFO/Sales | C43: =HistoricalFS!C90/HistoricalFS!C12 -> 0.16301809 | D43: =HistoricalFS!D90/HistoricalFS!D12 -> 0.18284236 | E43: =HistoricalFS!E90/HistoricalFS!E12 -> 0.07450861 | F43: =HistoricalFS!F90/HistoricalFS!F12 -> 0.15900845 | G43: =HistoricalFS!G90/HistoricalFS!G12 -> 0.057811699 | H43: =HistoricalFS!H90/HistoricalFS!H12 -> 0.15928933 | I43: =HistoricalFS!I90/HistoricalFS!I12 -> 0.13125573 | J43: =HistoricalFS!J90/HistoricalFS!J12 -> 0.17661931 | ... L43: =HistoricalFS!L90/HistoricalFS!L12 -> 0.1819631 | N43: =AVERAGE(C43:L43) -> 0.14719204 | O43: =MEDIAN(C43:L43) -> 0.16115371
B44: CFO/Total Assets | C44: =HistoricalFS!C90/HistoricalFS!C85 -> 0.070104499 | D44: =HistoricalFS!D90/HistoricalFS!D85 -> 0.088082557 | E44: =HistoricalFS!E90/HistoricalFS!E85 -> 0.042446598 | F44: =HistoricalFS!F90/HistoricalFS!F85 -> 0.081578484 | G44: =HistoricalFS!G90/HistoricalFS!G85 -> 0.020421722 | H44: =HistoricalFS!H90/HistoricalFS!H85 -> 0.073837165 | I44: =HistoricalFS!I90/HistoricalFS!I85 -> 0.071631664 | J44: =HistoricalFS!J90/HistoricalFS!J85 -> 0.090475018 | ... L44: =HistoricalFS!L90/HistoricalFS!L85 -> 0.088224543 | N44: =AVERAGE(C44:L44) -> 0.07184583 | O44: =MEDIAN(C44:L44) -> 0.077707824
B45: CFO/Total Debt | C45: =HistoricalFS!C90/HistoricalFS!C70 -> 0.22784228 | D45: =HistoricalFS!D90/HistoricalFS!D70 -> 0.29794074 | E45: =HistoricalFS!E90/HistoricalFS!E70 -> 0.1376148 | F45: =HistoricalFS!F90/HistoricalFS!F70 -> 0.26715906 | G45: =HistoricalFS!G90/HistoricalFS!G70 -> 0.096636818 | H45: =HistoricalFS!H90/HistoricalFS!H70 -> 0.34670602 | I45: =HistoricalFS!I90/HistoricalFS!I70 -> 0.2546849 | J45: =HistoricalFS!J90/HistoricalFS!J70 -> 0.45274992 | ... L45: =HistoricalFS!L90/HistoricalFS!L70 -> 0.47675215 | N45: =AVERAGE(C45:L45) -> 0.30355026 | O45: =MEDIAN(C45:L45) -> 0.2825499

Sheet Common Size Statement
B8: INR Crores | C8: =HistoricalFS!C9 -> 42825 | D8: =HistoricalFS!D9 -> 43190 | E8: =HistoricalFS!E9 -> 43555 | F8: =HistoricalFS!F9 -> 43921 | G8: =HistoricalFS!G9 -> 44286 | H8: =HistoricalFS!H9 -> 44651 | I8: =HistoricalFS!I9 -> 45016 | J8: =HistoricalFS!J9 -> 45382 | ... L8: =HistoricalFS!L9 -> 46112
A9: # | B9: Common Size Statement
B11: Sales | C11: =C37/C37 -> 1 | D11: =D37/D37 -> 1 | E11: =E37/E37 -> 1 | F11: =F37/F37 -> 1 | G11: =G37/G37 -> 1 | H11: =H37/H37 -> 1 | I11: =I37/I37 -> 1 | J11: =J37/J37 -> 1 | ... L11: =L37/L37 -> 1
B13: COGS | C13: =C40/C$37 -> 0.8128401 | D13: =D40/D$37 -> 0.79283717 | E13: =E40/E$37 -> 0.77574045 | F13: =F40/F$37 -> 0.75567432 | G13: =G40/G$37 -> 0.72373565 | H13: =H40/H$37 -> 0.78207013 | I13: =I40/I$37 -> 0.78541892 | J13: =J40/J$37 -> 0.7300201 | ... L13: =L40/L$37 -> 0.73166664
B15: Gross Profit | C15: =C42/C$37 -> 0.20432697 | D15: =D42/D$37 -> 0.22919327 | E15: =E42/E$37 -> 0.2324941 | F15: =F42/F$37 -> 0.25278584 | G15: =G42/G$37 -> 0.29570219 | H15: =H42/H$37 -> 0.24881779 | I15: =I42/I$37 -> 0.24911227 | J15: =J42/J$37 -> 0.27541124 | ... L15: =L42/L$37 -> 0.27805793
B17: Selling and admin | C17: =C44/C$37 -> 0.060930272 | D17: =D44/D$37 -> 0.074486404 | E17: =E44/E$37 -> 0.088364826 | F17: =F44/F$37 -> 0.1049509 | G17: =G44/G$37 -> 0.12042281 | H17: =H44/H$37 -> 0.091428629 | I17: =I44/I$37 -> 0.076870501 | J17: =J44/J$37 -> 0.085971608 | ... L17: =L44/L$37 -> 0.099190172
B19: Other Income | C19: =C46/C$37 -> 0.030340117 | D19: =D46/D$37 -> 0.02525184 | E19: =E46/E$37 -> 0.01479052 | F19: =F46/F$37 -> 0.014362832 | G19: =G46/G$37 -> 0.048105647 | H19: =H46/H$37 -> 0.028214714 | I19: =I46/I$37 -> 0.013715261 | J19: =J46/J$37 -> 0.017565384 | ... L19: =L46/L$37 -> 0.02732198
B21: Other Expenses | C21: =C48/C$37 -> -0.0089520125 | D21: =D48/D$37 -> -0.0098561241 | E21: =E48/E$37 -> -0.0041102374 | F21: =F48/F$37 -> -0.0017697958 | G21: =G48/G$37 -> 0.0020244174 | H21: =H48/H$37 -> 0.0010839632 | I21: =I48/I$37 -> 0.0098517109 | J21: =J48/J$37 -> 0.0086937081 | ... L21: =L48/L$37 -> 0.0092632935
B23: EBITDA | C23: =C50/C$37 -> 0.18268883 | D23: =D50/D$37 -> 0.18981483 | E23: =E50/E$37 -> 0.16303003 | F23: =F50/F$37 -> 0.16396756 | G23: =G50/G$37 -> 0.22136061 | H23: =H50/H$37 -> 0.18451991 | I23: =I50/I$37 -> 0.17610532 | J23: =J50/J$37 -> 0.19831131 | ... L23: =L50/L$37 -> 0.19692644
B25: Depreciation | C25: =C52/C$37 -> 0.038315008 | D25: =D52/D$37 -> 0.042745693 | E25: =E52/E$37 -> 0.03683378 | F25: =F52/F$37 -> 0.037210963 | G25: =G52/G$37 -> 0.056983918 | H25: =H52/H$37 -> 0.04287197 | I25: =I52/I$37 -> 0.045987202 | J25: =J52/J$37 -> 0.056540247 | ... L25: =L52/L$37 -> 0.054640171
B27: Interest | C27: =C54/C$37 -> 0.0126631 | D27: =D54/D$37 -> 0.020602677 | E27: =E54/E$37 -> 0.029023273 | F27: =F54/F$37 -> 0.036915997 | G27: =G54/G$37 -> 0.045440021 | H27: =H54/H$37 -> 0.02099405 | I27: =I54/I$37 -> 0.022331229 | J27: =J54/J$37 -> 0.025714066 | ... L27: =L54/L$37 -> 0.025631287
B29: Earning Before Tax | C29: =C56/C$37 -> 0.13171072 | D29: =D56/D$37 -> 0.12646646 | E29: =E56/E$37 -> 0.09717298 | F29: =F56/F$37 -> 0.089840601 | G29: =G56/G$37 -> 0.11893667 | H29: =H56/H$37 -> 0.12065389 | I29: =I56/I$37 -> 0.10778689 | J29: =J56/J$37 -> 0.116057 | ... L29: =L56/L$37 -> 0.11665498
B31: Tax | C31: =C58/C$37 -> 0.033560999 | D31: =D58/D$37 -> 0.034148451 | E31: =E58/E$37 -> 0.027079004 | F31: =F58/F$37 -> 0.023003994 | G31: =G58/G$37 -> 0.0036928461 | H31: =H58/H$37 -> 0.022989234 | I31: =I58/I$37 -> 0.023249764 | J31: =J58/J$37 -> 0.028593802 | ... L31: =L58/L$37 -> 0.026096346
B33: Net Profit | C33: =C60/C$37 -> 0.09814972 | D33: =D60/D$37 -> 0.092318006 | E33: =E60/E$37 -> 0.070093976 | F33: =F60/F$37 -> 0.066836607 | G33: =G60/G$37 -> 0.11524382 | H33: =H60/H$37 -> 0.097664657 | I33: =I60/I$37 -> 0.084537127 | J33: =J60/J$37 -> 0.087463197 | ... L33: =L60/L$37 -> 0.090558639
A35: # | B35: Historical Financial Statement
B36: Change Analysis | C36: 0
B37: Sales | C37: =HistoricalFS!C12*(1+$C$36) -> 303954 | D37: =HistoricalFS!D12*(1+$C$36) -> 390823 | E37: =HistoricalFS!E12*(1+$C$36) -> 568337 | F37: =HistoricalFS!F12*(1+$C$36) -> 596679 | G37: =HistoricalFS!G12*(1+$C$36) -> 466307 | H37: =HistoricalFS!H12*(1+$C$36) -> 694673 | I37: =HistoricalFS!I12*(1+$C$36) -> 876396 | J37: =HistoricalFS!J12*(1+$C$36) -> 899041 | ... L37: =HistoricalFS!L12*(1+$C$36) -> 1055780
B38: Changes In Inventory | C38: =HistoricalFS!C15*(1+$C$36) -> 5218 | D38: =HistoricalFS!D15*(1+$C$36) -> 8610 | E38: =HistoricalFS!E15*(1+$C$36) -> 4680 | F38: =HistoricalFS!F15*(1+$C$36) -> 5048 | G38: =HistoricalFS!G15*(1+$C$36) -> 9064 | H38: =HistoricalFS!H15*(1+$C$36) -> 21457 | I38: =HistoricalFS!I15*(1+$C$36) -> 30263 | J38: =HistoricalFS!J15*(1+$C$36) -> 4883 | ... L38: =HistoricalFS!L15*(1+$C$36) -> 10267
B40: COGS | C40: =HistoricalFS!C22*(1+$C$36) -> 247066 | D40: =HistoricalFS!D22*(1+$C$36) -> 309859 | E40: =HistoricalFS!E22*(1+$C$36) -> 440882 | F40: =HistoricalFS!F22*(1+$C$36) -> 450895 | G40: =HistoricalFS!G22*(1+$C$36) -> 337483 | H40: =HistoricalFS!H22*(1+$C$36) -> 543283 | I40: =HistoricalFS!I22*(1+$C$36) -> 688338 | J40: =HistoricalFS!J22*(1+$C$36) -> 656318 | ... L40: =HistoricalFS!L22*(1+$C$36) -> 772479
B42: Gross Profit | C42: =HistoricalFS!C25*(1+$C$36) -> 62106 | D42: =HistoricalFS!D25*(1+$C$36) -> 89574 | E42: =HistoricalFS!E25*(1+$C$36) -> 132135 | F42: =HistoricalFS!F25*(1+$C$36) -> 150832 | G42: =HistoricalFS!G25*(1+$C$36) -> 137888 | H42: =HistoricalFS!H25*(1+$C$36) -> 172847 | I42: =HistoricalFS!I25*(1+$C$36) -> 218321 | J42: =HistoricalFS!J25*(1+$C$36) -> 247606 | ... L42: =HistoricalFS!L25*(1+$C$36) -> 293568
B44: Selling and admin | C44: =HistoricalFS!C28*(1+$C$36) -> 18520 | D44: =HistoricalFS!D28*(1+$C$36) -> 29111 | E44: =HistoricalFS!E28*(1+$C$36) -> 50221 | F44: =HistoricalFS!F28*(1+$C$36) -> 62622 | G44: =HistoricalFS!G28*(1+$C$36) -> 56154 | H44: =HistoricalFS!H28*(1+$C$36) -> 63513 | I44: =HistoricalFS!I28*(1+$C$36) -> 67369 | J44: =HistoricalFS!J28*(1+$C$36) -> 77292 | ... L44: =HistoricalFS!L28*(1+$C$36) -> 104723
B46: Other Income | C46: =HistoricalFS!C31*(1+$C$36) -> 9222 | D46: =HistoricalFS!D31*(1+$C$36) -> 9869 | E46: =HistoricalFS!E31*(1+$C$36) -> 8406 | F46: =HistoricalFS!F31*(1+$C$36) -> 8570 | G46: =HistoricalFS!G31*(1+$C$36) -> 22432 | H46: =HistoricalFS!H31*(1+$C$36) -> 19600 | I46: =HistoricalFS!I31*(1+$C$36) -> 12020 | J46: =HistoricalFS!J31*(1+$C$36) -> 15792 | ... L46: =HistoricalFS!L31*(1+$C$36) -> 28846
B48: Other Expenses | C48: =HistoricalFS!C34*(1+$C$36) -> -2721 | D48: =HistoricalFS!D34*(1+$C$36) -> -3852 | E48: =HistoricalFS!E34*(1+$C$36) -> -2336 | F48: =HistoricalFS!F34*(1+$C$36) -> -1056 | G48: =HistoricalFS!G34*(1+$C$36) -> 944 | H48: =HistoricalFS!H34*(1+$C$36) -> 753 | I48: =HistoricalFS!I34*(1+$C$36) -> 8634 | J48: =HistoricalFS!J34*(1+$C$36) -> 7816 | ... L48: =HistoricalFS!L34*(1+$C$36) -> 9780
B50: EBITDA | C50: =HistoricalFS!C37*(1+$C$36) -> 55529 | D50: =HistoricalFS!D37*(1+$C$36) -> 74184 | E50: =HistoricalFS!E37*(1+$C$36) -> 92656 | F50: =HistoricalFS!F37*(1+$C$36) -> 97836 | G50: =HistoricalFS!G37*(1+$C$36) -> 103222 | H50: =HistoricalFS!H37*(1+$C$36) -> 128181 | I50: =HistoricalFS!I37*(1+$C$36) -> 154338 | J50: =HistoricalFS!J37*(1+$C$36) -> 178290 | ... L50: =HistoricalFS!L37*(1+$C$36) -> 207911
B52: Depreciation | C52: =HistoricalFS!C40*(1+$C$36) -> 11646 | D52: =HistoricalFS!D40*(1+$C$36) -> 16706 | E52: =HistoricalFS!E40*(1+$C$36) -> 20934 | F52: =HistoricalFS!F40*(1+$C$36) -> 22203 | G52: =HistoricalFS!G40*(1+$C$36) -> 26572 | H52: =HistoricalFS!H40*(1+$C$36) -> 29782 | I52: =HistoricalFS!I40*(1+$C$36) -> 40303 | J52: =HistoricalFS!J40*(1+$C$36) -> 50832 | ... L52: =HistoricalFS!L40*(1+$C$36) -> 57688
B54: Interest | C54: =HistoricalFS!C43*(1+$C$36) -> 3849 | D54: =HistoricalFS!D43*(1+$C$36) -> 8052 | E54: =HistoricalFS!E43*(1+$C$36) -> 16495 | F54: =HistoricalFS!F43*(1+$C$36) -> 22027 | G54: =HistoricalFS!G43*(1+$C$36) -> 21189 | H54: =HistoricalFS!H43*(1+$C$36) -> 14584 | I54: =HistoricalFS!I43*(1+$C$36) -> 19571 | J54: =HistoricalFS!J43*(1+$C$36) -> 23118 | ... L54: =HistoricalFS!L43*(1+$C$36) -> 27061
B56: Earning Before Tax | C56: =HistoricalFS!C46*(1+$C$36) -> 40034 | D56: =HistoricalFS!D46*(1+$C$36) -> 49426 | E56: =HistoricalFS!E46*(1+$C$36) -> 55227 | F56: =HistoricalFS!F46*(1+$C$36) -> 53606 | G56: =HistoricalFS!G46*(1+$C$36) -> 55461 | H56: =HistoricalFS!H46*(1+$C$36) -> 83815 | I56: =HistoricalFS!I46*(1+$C$36) -> 94464 | J56: =HistoricalFS!J46*(1+$C$36) -> 104340 | ... L56: =HistoricalFS!L46*(1+$C$36) -> 123162
B58: Tax | C58: =HistoricalFS!C49*(1+$C$36) -> 10201 | D58: =HistoricalFS!D49*(1+$C$36) -> 13346 | E58: =HistoricalFS!E49*(1+$C$36) -> 15390 | F58: =HistoricalFS!F49*(1+$C$36) -> 13726 | G58: =HistoricalFS!G49*(1+$C$36) -> 1722 | H58: =HistoricalFS!H49*(1+$C$36) -> 15970 | I58: =HistoricalFS!I49*(1+$C$36) -> 20376 | J58: =HistoricalFS!J49*(1+$C$36) -> 25707 | ... L58: =HistoricalFS!L49*(1+$C$36) -> 27552
B60: Net Profit | C60: =HistoricalFS!C52*(1+$C$36) -> 29833 | D60: =HistoricalFS!D52*(1+$C$36) -> 36080 | E60: =HistoricalFS!E52*(1+$C$36) -> 39837 | F60: =HistoricalFS!F52*(1+$C$36) -> 39880 | G60: =HistoricalFS!G52*(1+$C$36) -> 53739 | H60: =HistoricalFS!H52*(1+$C$36) -> 67845 | I60: =HistoricalFS!I52*(1+$C$36) -> 74088 | J60: =HistoricalFS!J52*(1+$C$36) -> 78633 | ... L60: =HistoricalFS!L52*(1+$C$36) -> 95610

Sheet Forcasting
B12: Forcasting of Revenue | H12: SUMMARY OUTPUT
B14: Year Weight | C14: Year | D14: Sales | E14: Sales Growth | H14: Regression Statistics
B15: 1 | C15: ='Ratio Analysis'!C9 -> 42825 | D15: 303954 | H15: Multiple R | I15: 0.96035656
B16: =B15+1 -> 2 | C16: =C15+365 -> 43190 | D16: 390823 | E16: =D16/D15-1 -> 0.28579654 | H16: R Square | I16: 0.92228471
B17: =B16+1 -> 3 | C17: =C16+365 -> 43555 | D17: 568337 | E17: =D17/D16-1 -> 0.45420561 | H17: Adjusted R Square | I17: 0.9125703
B18: =B17+1 -> 4 | C18: =C17+365 -> 43920 | D18: 596679 | E18: =D18/D17-1 -> 0.0498683 | H18: Standard Error | I18: 76221.481
B19: =B18+1 -> 5 | C19: =C18+365 -> 44285 | D19: 466307 | E19: =D19/D18-1 -> -0.21849604 | H19: Observations | I19: 10
B20: =B19+1 -> 6 | C20: =C19+365 -> 44650 | D20: 694673 | E20: =D20/D19-1 -> 0.48973316
B21: =B20+1 -> 7 | C21: =C20+365 -> 45015 | D21: 876396 | E21: =D21/D20-1 -> 0.26159502 | H21: ANOVA
B22: =B21+1 -> 8 | C22: =C21+365 -> 45380 | D22: 899041 | E22: =D22/D21-1 -> 0.025838776 | I22: df | J22: SS | K22: MS | L22: F | M22: Significance F
B23: =B22+1 -> 9 | C23: =C22+365 -> 45745 | D23: 962820 | E23: =D23/D22-1 -> 0.070941147 | H23: Regression | I23: 1 | J23: 5.515734e+11 | K23: 5.515734e+11 | L23: 94.939852 | M23: 1.0300346e-05
B24: =B23+1 -> 10 | C24: =C23+365 -> 46110 | D24: 1055780 | E24: =D24/D23-1 -> 0.096549719 | H24: Residual | I24: 8 | J24: 4.6477714e+10 | K24: 5.8097142e+09
B25: =B24+1 -> 11 | C25: =C24+365 -> 46475 | D25: =$I$28+B25*$I$29 -> 1131196 | E25: =D25/D24-1 -> 0.071431548 | H25: Total | I25: 9 | J25: 598051116920
B26: =B25+1 -> 12 | C26: =C25+365 -> 46840 | D26: =$I$28+B26*$I$29 -> 1212962.4 | E26: =D26/D25-1 -> 0.072283109
B27: =B26+1 -> 13 | C27: =C26+365 -> 47205 | D27: =$I$28+B27*$I$29 -> 1294728.7 | E27: =D27/D26-1 -> 0.067410471 | I27: Coefficients | J27: Standard Error | K27: t Stat | L27: P-value | M27: Lower 95% | N27: Upper 95% | O27: Lower 95.0% | P27: Upper 95.0%
B28: =B27+1 -> 14 | C28: =C27+365 -> 47570 | D28: =$I$28+B28*$I$29 -> 1376495.1 | E28: =D28/D27-1 -> 0.063153278 | H28: Intercept | I28: 231766 | J28: 52069.184 | K28: 4.4511164 | L28: 0.0021361276 | M28: 111694.25 | N28: 351837.75 | O28: 111694.25 | P28: 351837.75
H29: Year Weight | I29: 81766.364 | J29: 8391.7089 | K29: 9.7437083 | L29: 1.0300346e-05 | M29: 62415.048 | N29: 101117.68 | O29: 62415.048 | P29: 101117.68

Sheet intrinsic Growth
B8: Calculation Of ROIC | C8: =RawFs!E2 -> 42795 | D8: =RawFs!F2 -> 43160 | E8: =RawFs!G2 -> 43525 | F8: =RawFs!H2 -> 43891 | G8: =RawFs!I2 -> 44256 | H8: =RawFs!J2 -> 44621 | I8: =RawFs!K2 -> 44986 | J8: =RawFs!L2 -> 45352 | ... L8: =RawFs!N2 -> 46082
A10: # | B10: Current Asset
B11: Inventories | C11: =RawFs!E31 -> 48951 | D11: =RawFs!F31 -> 60837 | E11: =RawFs!G31 -> 67561 | F11: =RawFs!H31 -> 73903 | G11: =RawFs!I31 -> 81672 | H11: =RawFs!J31 -> 107778 | I11: =RawFs!K31 -> 140008 | J11: =RawFs!L31 -> 152770 | ... L11: =RawFs!N31 -> 166941
B12: Trade Receivables | C12: =RawFs!E32 -> 8177 | D12: =RawFs!F32 -> 17555 | E12: =RawFs!G32 -> 30089 | F12: =RawFs!H32 -> 19656 | G12: =RawFs!I32 -> 19014 | H12: =RawFs!J32 -> 23640 | I12: =RawFs!K32 -> 28448 | J12: =RawFs!L32 -> 31628 | ... L12: =RawFs!N32 -> 58491
B13: Loan n Advances | C13: =RawFs!E34 -> 996 | D13: =RawFs!F34 -> 2327 | E13: =RawFs!G34 -> 545 | F13: =RawFs!H34 -> 669 | G13: =RawFs!I34 -> 65 | H13: =RawFs!J34 -> 130 | I13: =RawFs!K34 -> 176 | J13: =RawFs!L34 -> 2517 | ... L13: =RawFs!N34 -> 4870
B14: Other Assets Items | C14: =RawFs!E35 -> 39393 | D14: =RawFs!F35 -> 52530 | E14: =RawFs!G35 -> 74882 | F14: =RawFs!H35 -> 119336 | G14: =RawFs!I35 -> 169878 | H14: =RawFs!J35 -> 136328 | I14: =RawFs!K35 -> 114469 | J14: =RawFs!L35 -> 126396 | ... L14: =RawFs!N35 -> 190454
B15: Total Assets | C15: =SUM(C11:C14) -> 97517 | D15: =SUM(D11:D14) -> 133249 | E15: =SUM(E11:E14) -> 173077 | F15: =SUM(F11:F14) -> 213564 | G15: =SUM(G11:G14) -> 270629 | H15: =SUM(H11:H14) -> 267876 | I15: =SUM(I11:I14) -> 283101 | J15: =SUM(J11:J14) -> 313311 | ... L15: =SUM(L11:L14) -> 420756
B17: Current Liabilities
B18: Trade Payable | C18: =RawFs!E12 -> 76595 | D18: =RawFs!F12 -> 106861 | E18: =RawFs!G12 -> 108309 | F18: =RawFs!H12 -> 96799 | G18: =RawFs!I12 -> 108897 | H18: =RawFs!J12 -> 159330 | I18: =RawFs!K12 -> 147172 | J18: =RawFs!L12 -> 178377 | ... L18: =RawFs!N12 -> 158842
B19: Other Liablities | C19: =RawFs!E13 -> 146106 | D19: =RawFs!F13 -> 167524 | E19: =RawFs!G13 -> 186215 | F19: =RawFs!H13 -> 249736 | G19: =RawFs!I13 -> 132774 | H19: =RawFs!J13 -> 131150 | I19: =RawFs!K13 -> 178165 | J19: =RawFs!L13 -> 300164 | ... L19: =RawFs!N13 -> 529876
A21: # | B21: Total Liabilities | C21: =SUM(C18:C20) -> 222701 | D21: =SUM(D18:D20) -> 274385 | E21: =SUM(E18:E20) -> 294524 | F21: =SUM(F18:F20) -> 346535 | G21: =SUM(G18:G20) -> 241671 | H21: =SUM(H18:H20) -> 290480 | I21: =SUM(I18:I20) -> 325337 | J21: =SUM(J18:J20) -> 478541 | ... L21: =SUM(L18:L20) -> 688718
A23: # | B23: Net Working Capital | C23: =C15-C21 -> -125184 | D23: =D15-D21 -> -141136 | E23: =E15-E21 -> -121447 | F23: =F15-F21 -> -132971 | G23: =G15-G21 -> 28958 | H23: =H15-H21 -> -22604 | I23: =I15-I21 -> -42236 | J23: =J15-J21 -> -165230 | ... L23: =L15-L21 -> -267962
A25: # | B25: Non Current Assets
B26: Land | C26: =RawFs!E17 -> 65973 | D26: =RawFs!F17 -> 66765 | E26: =RawFs!G17 -> 49371 | F26: =RawFs!H17 -> 68743 | G26: =RawFs!I17 -> 68768 | H26: =RawFs!J17 -> 69855 | I26: =RawFs!K17 -> 79697 | J26: =RawFs!L17 -> 87287 | ... L26: =RawFs!N17 -> 103974
B27: Building | C27: =RawFs!E18 -> 18813 | D27: =RawFs!F18 -> 22194 | E27: =RawFs!G18 -> 27672 | F27: =RawFs!H18 -> 34380 | G27: =RawFs!I18 -> 36781 | H27: =RawFs!J18 -> 47561 | I27: =RawFs!K18 -> 69747 | J27: =RawFs!L18 -> 82062 | ... L27: =RawFs!N18 -> 110548
B28: Plant Machinery | C28: =RawFs!E19 -> 179326 | D28: =RawFs!F19 -> 325183 | E28: =RawFs!G19 -> 318853 | F28: =RawFs!H19 -> 449770 | G28: =RawFs!I19 -> 471201 | H28: =RawFs!J19 -> 518865 | I28: =RawFs!K19 -> 557687 | J28: =RawFs!L19 -> 579067 | ... L28: =RawFs!N19 -> 727877
B29: Ships Vessels | C29: =RawFs!E20 -> 3484 | D29: =RawFs!F20 -> 5038 | E29: =RawFs!G20 -> 417 | F29: =RawFs!H20 -> 502 | G29: =RawFs!I20 -> 515 | H29: =RawFs!J20 -> 508 | I29: =RawFs!K20 -> 518 | J29: =RawFs!L20 -> 522 | ... L29: =RawFs!N20 -> 551
B30: Equipments | C30: =RawFs!E21 -> 0 | D30: =RawFs!F21 -> 0 | E30: =RawFs!G21 -> 0 | F30: =RawFs!H21 -> 0 | G30: =RawFs!I21 -> 0 | H30: =RawFs!J21 -> 32638 | I30: =RawFs!K21 -> 45067 | J30: =RawFs!L21 -> 59936 | ... L30: =RawFs!N21 -> 0
B31: Furniture n fittings | C31: =RawFs!E22 -> 7848 | D31: =RawFs!F22 -> 10146 | E31: =RawFs!G22 -> 21817 | F31: =RawFs!H22 -> 31211 | G31: =RawFs!I22 -> 38039 | H31: =RawFs!J22 -> 24970 | I31: =RawFs!K22 -> 38161 | J31: =RawFs!L22 -> 43458 | ... L31: =RawFs!N22 -> 121211
B32: Vehicles | C32: =RawFs!E23 -> 1155 | D32: =RawFs!F23 -> 1199 | E32: =RawFs!G23 -> 1240 | F32: =RawFs!H23 -> 1411 | G32: =RawFs!I23 -> 2336 | H32: =RawFs!J23 -> 2530 | I32: =RawFs!K23 -> 3667 | J32: =RawFs!L23 -> 3745 | ... L32: =RawFs!N23 -> 5044
B33: Intangible Assets | C33: =RawFs!E24 -> 75351 | D33: =RawFs!F24 -> 76599 | E33: =RawFs!G24 -> 86765 | F33: =RawFs!H24 -> 81462 | G33: =RawFs!I24 -> 77353 | H33: =RawFs!J24 -> 65970 | I33: =RawFs!K24 -> 85032 | J33: =RawFs!L24 -> 112873 | ... L33: =RawFs!N24 -> 167504
B34: Other fixed assets | C34: =RawFs!E25 -> 9343 | D34: =RawFs!F25 -> 74160 | E34: =RawFs!G25 -> 90387 | F34: =RawFs!H25 -> 76299 | G34: =RawFs!I25 -> 80819 | H34: =RawFs!J25 -> 120717 | I34: =RawFs!K25 -> 138426 | J34: =RawFs!L25 -> 145632 | ... L34: =RawFs!N25 -> 318878
B35: Gross Block | C35: =SUM(C26:C34) -> 361293 | D35: =SUM(D26:D34) -> 581284 | E35: =SUM(E26:E34) -> 596522 | F35: =SUM(F26:F34) -> 743778 | G35: =SUM(G26:G34) -> 775812 | H35: =SUM(H26:H34) -> 883614 | I35: =SUM(I26:I34) -> 1018002 | J35: =SUM(J26:J34) -> 1114582 | ... L35: =SUM(L26:L34) -> 1555587
B36: Accumulated Depreciation | C36: =-RawFs!E27 -> -162767 | D36: =-RawFs!F27 -> -177399 | E36: =-RawFs!G27 -> -198148 | F36: =-RawFs!H27 -> -211120 | G36: =-RawFs!I27 -> -234554 | H36: =-RawFs!J27 -> -255816 | I36: =-RawFs!K27 -> -293197 | J36: =-RawFs!L27 -> -334597 | ... L36: =-RawFs!N27 -> -430792
A37: # | B37: Net Non Current Assets | C37: =SUM(C35:C36) -> 198526 | D37: =SUM(D35:D36) -> 403885 | E37: =SUM(E35:E36) -> 398374 | F37: =SUM(F35:F36) -> 532658 | G37: =SUM(G35:G36) -> 541258 | H37: =SUM(H35:H36) -> 627798 | I37: =SUM(I35:I36) -> 724805 | J37: =SUM(J35:J36) -> 779985 | ... L37: =SUM(L35:L36) -> 1124795
A40: # | B40: Invested Capital | C40: =SUM(C37,C23) -> 73342 | D40: =SUM(D37,D23) -> 262749 | E40: =SUM(E37,E23) -> 276927 | F40: =SUM(F37,F23) -> 399687 | G40: =SUM(G37,G23) -> 570216 | H40: =SUM(H37,H23) -> 605194 | I40: =SUM(I37,I23) -> 682569 | J40: =SUM(J37,J23) -> 614755 | ... L40: =SUM(L37,L23) -> 856833
B41: EBIT | C41: =SUM('Data Sheet '!B28:B29) -> 43883 | D41: =SUM('Data Sheet '!C28:C29) -> 57478 | E41: =SUM('Data Sheet '!D28:D29) -> 71722 | F41: =SUM('Data Sheet '!E28:E29) -> 75633 | G41: =SUM('Data Sheet '!F28:F29) -> 76650 | H41: =SUM('Data Sheet '!G28:G29) -> 98399 | I41: =SUM('Data Sheet '!H28:H29) -> 114035 | J41: =SUM('Data Sheet '!I28:I29) -> 127458 | ... L41: =SUM('Data Sheet '!K28:K29) -> 150223
B43: ROIC | C43: =C41/C40 -> 0.59833383 | D43: =D41/D40 -> 0.2187563 | E43: =E41/E40 -> 0.25899244 | F43: =F41/F40 -> 0.18923057 | G43: =G41/G40 -> 0.13442275 | H43: =H41/H40 -> 0.16259084 | I43: =I41/I40 -> 0.16706736 | J43: =J41/J40 -> 0.20733138 | ... L43: =L41/L40 -> 0.17532355
B45: Calculation Of Reinvestment Rate | C45: =C8 -> 42795 | D45: =D8 -> 43160 | E45: =E8 -> 43525 | F45: =F8 -> 43891 | G45: =G8 -> 44256 | H45: =H8 -> 44621 | I45: =I8 -> 44986 | J45: =J8 -> 45352 | ... L45: =L8 -> 46082
B47: Net Capex | C47: =-SUM(RawFs!E48:E49) -> 76627 | D47: =-SUM(RawFs!F48:F49) -> 72954 | E47: =-SUM(RawFs!G48:G49) -> 92777 | F47: =-SUM(RawFs!H48:H49) -> 75553 | G47: =-SUM(RawFs!I48:I49) -> 103518 | H47: =-SUM(RawFs!J48:J49) -> 97008 | I47: =-SUM(RawFs!K48:K49) -> 131802 | J47: =-SUM(RawFs!L48:L49) -> 137576 | ... L47: =-SUM(RawFs!N48:N49) -> 122090
B48: Change In Working Capital | D48: =D23-C23 -> -15952 | E48: =E23-D23 -> 19689 | F48: =F23-E23 -> -11524 | G48: =G23-F23 -> 161929 | H48: =H23-G23 -> -51562 | I48: =I23-H23 -> -19632 | J48: =J23-I23 -> -122994 | K48: =K23-J23 -> -61465 | L48: =L23-K23 -> -41267
B50: EBIT | C50: =C41 -> 43883 | D50: =D41 -> 57478 | E50: =E41 -> 71722 | F50: =F41 -> 75633 | G50: =G41 -> 76650 | H50: =H41 -> 98399 | I50: =I41 -> 114035 | J50: =J41 -> 127458 | ... L50: =L41 -> 150223
B51: Marginal Tax Rate | C51: 0.25 | D51: 0.25 | E51: 0.25 | F51: 0.25 | G51: 0.25 | H51: 0.25 | I51: 0.25 | J51: 0.25 | K51: 0.25 | L51: 0.25
B52: EBIT(1-Tax Rate) | C52: =C50*(1-C51) -> 32912.25 | D52: =D50*(1-D51) -> 43108.5 | E52: =E50*(1-E51) -> 53791.5 | F52: =F50*(1-F51) -> 56724.75 | G52: =G50*(1-G51) -> 57487.5 | H52: =H50*(1-H51) -> 73799.25 | I52: =I50*(1-I51) -> 85526.25 | J52: =J50*(1-J51) -> 95593.5 | ... L52: =L50*(1-L51) -> 112667.25
B54: Reinvestment | D54: =SUM(D47:D48) -> 57002 | E54: =SUM(E47:E48) -> 112466 | F54: =SUM(F47:F48) -> 64029 | G54: =SUM(G47:G48) -> 265447 | H54: =SUM(H47:H48) -> 45446 | I54: =SUM(I47:I48) -> 112170 | J54: =SUM(J47:J48) -> 14582 | K54: =SUM(K47:K48) -> 76159 | L54: =SUM(L47:L48) -> 80823
A55: # | B55: Reinvestment Rate | D55: =D54/D52 -> 1.3222914 | E55: =E54/E52 -> 2.0907764 | F55: =F54/F52 -> 1.1287665 | G55: =G54/G52 -> 4.6174734 | H55: =H54/H52 -> 0.61580572 | I55: =I54/I52 -> 1.3115272 | J55: =J54/J52 -> 0.15254175 | K55: =K54/K52 -> 0.77940326 | L55: =L54/L52 -> 0.71736019
K57: 4 Year Average | L57: =AVERAGE(I55:L55) -> 0.74020809
K58: 4 Year Median | L58: =MEDIAN(I55:L55) -> 0.74838173
B60: Calculation Of Growth Rate | C60: =C45 -> 42795 | D60: =D45 -> 43160 | E60: =E45 -> 43525 | F60: =F45 -> 43891 | G60: =G45 -> 44256 | H60: =H45 -> 44621 | I60: =I45 -> 44986 | J60: =J45 -> 45352 | ... L60: =L45 -> 46082
B62: Reinvestment Rate | D62: =D55 -> 1.3222914 | E62: =E55 -> 2.0907764 | F62: =F55 -> 1.1287665 | G62: =G55 -> 4.6174734 | H62: =H55 -> 0.61580572 | I62: =I55 -> 1.3115272 | J62: =J55 -> 0.15254175 | K62: =K55 -> 0.77940326 | L62: =L55 -> 0.71736019
...

Sheet RawFs
B2: Particlar | C2: 42064 | D2: 42430 | E2: 42795 | F2: 43160 | G2: 43525 | H2: 43891 | I2: 44256 | J2: 44621 | K2: 44986 | L2: 45352 | M2: 45717 | N2: 46082
B3: Equity Capital | C3: 2943 | D3: 2948 | E3: 2959 | F3: 5922 | G3: 5926 | H3: 6339 | I3: 6445 | J3: 6765 | K3: 6766 | L3: 6766 | M3: 13532 | N3: 13532
B4: Reserves | C4: 215556 | D4: 228608 | E4: 260750 | F4: 287584 | G4: 381186 | H4: 442827 | I4: 693727 | J4: 772720 | K4: 709106 | L4: 786715 | M4: 829668 | N4: 890498
B5: Borrowings - | C5: 168251 | D5: 194714 | E5: 217475 | F5: 239843 | G5: 307714 | H5: 355133 | I5: 278962 | J5: 319158 | K5: 451664 | L5: 350719 | M5: 374313 | N5: 402962
B6: Long term Borrowings | C6: 128165 | D6: 154957 | E6: 172285 | F6: 164385 | G6: 226345 | H6: 216470 | I6: 182520 | J6: 224883 | K6: 296023 | L6: 222712 | M6: 236899 | N6: 270751
B7: Short term Borrowings | C7: 27965 | D7: 23545 | E7: 31528 | F7: 37429 | G7: 64436 | H7: 93786 | I7: 88128 | J7: 78606 | K7: 130790 | L7: 101910 | M7: 110631 | N7: 103670
B8: Lease Liabilities | C8: 0 | D8: 0 | E8: 0 | F8: 0 | G8: 0 | H8: 0 | I8: 8314 | J8: 15669 | K8: 20426 | L8: 21520 | M8: 22045 | N8: 23579
B9: Other Borrowings | C9: 12121 | D9: 16212 | E9: 13662 | F9: 38029 | G9: 16933 | H9: 44877 | I9: 0 | J9: 0 | K9: 4425 | L9: 4577 | M9: 4738 | N9: 4962
B10: Other Liabilities - | C10: 117736 | D10: 172727 | E10: 225618 | F10: 277924 | G10: 302804 | H10: 358716 | I10: 340931 | J10: 399979 | K10: 438346 | L10: 610848 | M10: 732200 | N10: 870554
B11: Non controlling int | C11: 3038 | D11: 3356 | E11: 2917 | F11: 3539 | G11: 8280 | H11: 12181 | I11: 99260 | J11: 109499 | K11: 113009 | L11: 132307 | M11: 166426 | N11: 181836
B12: Trade Payables | C12: 59407 | D12: 60296 | E12: 76595 | F12: 106861 | G12: 108309 | H12: 96799 | I12: 108897 | J12: 159330 | K12: 147172 | L12: 178377 | M12: 186789 | N12: 158842
B13: Other liability items | C13: 55291 | D13: 109075 | E13: 146106 | F13: 167524 | G13: 186215 | H13: 249736 | I13: 132774 | J13: 131150 | K13: 178165 | L13: 300164 | M13: 378985 | N13: 529876
... B36: Total Assets | C36: 504486 | D36: 598997 | E36: 706802 | F36: 811273 | G36: 997630 | H36: 1163015 | I36: 1320065 | J36: 1498622 | K36: 1605882 | L36: 1755048 | M36: 1949713 | N36: 2177546
C39: 42064 | D39: 42430 | E39: 42795 | F39: 43160 | G39: 43525 | H39: 43891 | I39: 44256 | J39: 44621 | K39: 44986 | L39: 45352 | M39: 45717 | N39: 46082
